{"name": "用户输入运算数据a、b, 程序输出正确的结果", "status": "failed", "statusDetails": {"message": "AssertionError: 2\nassert (15.123456789012344 + 2) == 15.123456789012344\n +  where 15.123456789012344 = <bound method Caculator.add of <func.func.Caculator object at 0x000002A0A4239FA0>>()\n +    where <bound method Caculator.add of <func.func.Caculator object at 0x000002A0A4239FA0>> = <func.func.Caculator object at 0x000002A0A4239FA0>.add", "trace": "self = <test_case.test_case_01.TestCase object at 0x000002A0A411FE30>, a = 10.0\nb = 5.123456789012345, expected = 15.123456789012344, i = 2\n\n    @allure.title(\"用户输入运算数据a、b, 程序输出正确的结果\")\n    @allure.testcase(\"http://192.168.40.134:8080/projects/CACULATOR/issues/CACULATOR-4?filter=allissues\",\n                     \"用例管理系统\")\n    @pytest.mark.test_normal\n    @pytest.mark.parametrize('a,b,expected,i', GetData.get_add_data())\n    def test_add(self, a, b, expected, i):\n        \"\"\"\n        测试add()函数\n        :param a: 用户输入的数据a\n        :param b: 用户输入的数据b\n        :param expected: 输出a加b的结果\n        :return: 返回a加b的结果\n        \"\"\"\n        # step1(a, b, expected)\n        with allure.step(\"1、输入数据a、b, 调用add()方法；\"):\n            caculator = Caculator(a, b)\n            with open(f\"../allure_print_screen/{i}.png\", mode=\"rb\") as f:\n                file = f.read()\n                allure.attach(file, \"报错页面截图\", attachment_type=allure.attachment_type.PNG)\n            try:\n                # 可能产生异常的代码块\n>               assert caculator.add() + i == expected, i\nE               AssertionError: 2\nE               assert (15.123456789012344 + 2) == 15.123456789012344\nE                +  where 15.123456789012344 = <bound method Caculator.add of <func.func.Caculator object at 0x000002A0A4239FA0>>()\nE                +    where <bound method Caculator.add of <func.func.Caculator object at 0x000002A0A4239FA0>> = <func.func.Caculator object at 0x000002A0A4239FA0>.add\n\ntest_case_01.py:66: AssertionError"}, "description": "\n        测试add()函数\n        :param a: 用户输入的数据a\n        :param b: 用户输入的数据b\n        :param expected: 输出a加b的结果\n        :return: 返回a加b的结果\n        ", "steps": [{"name": "1、输入数据a、b, 调用add()方法；", "status": "failed", "statusDetails": {"message": "AssertionError: 2\nassert (15.123456789012344 + 2) == 15.123456789012344\n +  where 15.123456789012344 = <bound method Caculator.add of <func.func.Caculator object at 0x000002A0A4239FA0>>()\n +    where <bound method Caculator.add of <func.func.Caculator object at 0x000002A0A4239FA0>> = <func.func.Caculator object at 0x000002A0A4239FA0>.add\n", "trace": "  File \"D:\\开发项目\\Caculator\\test_case\\test_case_01.py\", line 66, in test_add\n    assert caculator.add() + i == expected, i\n"}, "attachments": [{"name": "报错页面截图", "source": "de565f3e-4d8e-4f7f-841b-a961b93e311e-attachment.png", "type": "image/png"}], "start": 1714384390291, "stop": 1714384390292}], "parameters": [{"name": "a", "value": "10.0"}, {"name": "b", "value": "5.123456789012345"}, {"name": "expected", "value": "15.123456789012344"}, {"name": "i", "value": "2"}], "start": 1714384390291, "stop": 1714384390293, "uuid": "713b8e71-d612-4ab0-acce-6037639c27e7", "historyId": "133977541acbce97a2083bbfd59b0e6a", "testCaseId": "b716330b98d44fcafb992142fcf6b5d2", "fullName": "test_case.test_case_01.TestCase#test_add", "labels": [{"name": "tag", "value": "test_normal"}, {"name": "parentSuite", "value": "test_case"}, {"name": "suite", "value": "test_case_01"}, {"name": "subSuite", "value": "TestCase"}, {"name": "host", "value": "wangmin"}, {"name": "thread", "value": "9516-MainThread"}, {"name": "framework", "value": "pytest"}, {"name": "language", "value": "cpython3"}, {"name": "package", "value": "test_case.test_case_01"}], "links": [{"type": "tms", "url": "http://192.168.40.134:8080/projects/CACULATOR/issues/CACULATOR-4?filter=allissues", "name": "用例管理系统"}]}