{"name": "用户输入运算数据a、b, 程序输出正确的结果", "status": "failed", "statusDetails": {"message": "AssertionError: 1\nassert (2 + 1) == 2\n +  where 2 = <bound method Caculator.add of <func.func.Caculator object at 0x000002A0A3FDBE30>>()\n +    where <bound method Caculator.add of <func.func.Caculator object at 0x000002A0A3FDBE30>> = <func.func.Caculator object at 0x000002A0A3FDBE30>.add", "trace": "self = <test_case.test_case_01.TestCase object at 0x000002A0A4187620>, a = 1\nb = 1, expected = 2, i = 1\n\n    @allure.title(\"用户输入运算数据a、b, 程序输出正确的结果\")\n    @allure.testcase(\"http://192.168.40.134:8080/projects/CACULATOR/issues/CACULATOR-4?filter=allissues\",\n                     \"用例管理系统\")\n    @pytest.mark.test_normal\n    @pytest.mark.parametrize('a,b,expected,i', GetData.get_add_data())\n    def test_add(self, a, b, expected, i):\n        \"\"\"\n        测试add()函数\n        :param a: 用户输入的数据a\n        :param b: 用户输入的数据b\n        :param expected: 输出a加b的结果\n        :return: 返回a加b的结果\n        \"\"\"\n        # step1(a, b, expected)\n        with allure.step(\"1、输入数据a、b, 调用add()方法；\"):\n            caculator = Caculator(a, b)\n            with open(f\"../allure_print_screen/{i}.png\", mode=\"rb\") as f:\n                file = f.read()\n                allure.attach(file, \"报错页面截图\", attachment_type=allure.attachment_type.PNG)\n            try:\n                # 可能产生异常的代码块\n>               assert caculator.add() + i == expected, i\nE               AssertionError: 1\nE               assert (2 + 1) == 2\nE                +  where 2 = <bound method Caculator.add of <func.func.Caculator object at 0x000002A0A3FDBE30>>()\nE                +    where <bound method Caculator.add of <func.func.Caculator object at 0x000002A0A3FDBE30>> = <func.func.Caculator object at 0x000002A0A3FDBE30>.add\n\ntest_case_01.py:66: AssertionError"}, "description": "\n        测试add()函数\n        :param a: 用户输入的数据a\n        :param b: 用户输入的数据b\n        :param expected: 输出a加b的结果\n        :return: 返回a加b的结果\n        ", "steps": [{"name": "1、输入数据a、b, 调用add()方法；", "status": "failed", "statusDetails": {"message": "AssertionError: 1\nassert (2 + 1) == 2\n +  where 2 = <bound method Caculator.add of <func.func.Caculator object at 0x000002A0A3FDBE30>>()\n +    where <bound method Caculator.add of <func.func.Caculator object at 0x000002A0A3FDBE30>> = <func.func.Caculator object at 0x000002A0A3FDBE30>.add\n", "trace": "  File \"D:\\开发项目\\Caculator\\test_case\\test_case_01.py\", line 66, in test_add\n    assert caculator.add() + i == expected, i\n"}, "attachments": [{"name": "报错页面截图", "source": "de66d34a-628e-43fb-8e00-f0d3fb1a26f8-attachment.png", "type": "image/png"}], "start": 1714384390258, "stop": 1714384390258}], "parameters": [{"name": "a", "value": "1"}, {"name": "b", "value": "1"}, {"name": "expected", "value": "2"}, {"name": "i", "value": "1"}], "start": 1714384390258, "stop": 1714384390259, "uuid": "40fd460c-6c14-4338-8e8d-e731f406a3b0", "historyId": "54b835993904f023ac9636599037c4a0", "testCaseId": "b716330b98d44fcafb992142fcf6b5d2", "fullName": "test_case.test_case_01.TestCase#test_add", "labels": [{"name": "tag", "value": "test_normal"}, {"name": "parentSuite", "value": "test_case"}, {"name": "suite", "value": "test_case_01"}, {"name": "subSuite", "value": "TestCase"}, {"name": "host", "value": "wangmin"}, {"name": "thread", "value": "9516-MainThread"}, {"name": "framework", "value": "pytest"}, {"name": "language", "value": "cpython3"}, {"name": "package", "value": "test_case.test_case_01"}], "links": [{"type": "tms", "url": "http://192.168.40.134:8080/projects/CACULATOR/issues/CACULATOR-4?filter=allissues", "name": "用例管理系统"}]}